Workbook

Sheet Overview
B2: Aethos for Professional Services
B3: 10-Tenant E2E Demo & Test — Execution Tracker
B5: Companion to | C5: Aethos-PS-Test-Scenario-Library.md
B6: Platform | C6: https://aethos.ishirock.tech (agent-first PS ERP)
B7: Protocol | C7: Agentic-first (Atlas chat) -> Inbox approval -> UI evidence. Then verify manual fallback.
B8: Build rule | C8: No backend seeding. Every record created via signup / Atlas / CRUD and visible in a module screen.
B9: How to use | C9: Set Result per step on the Execution tab (Pass / Fail / Blocked / N/A). Summary updates automatically.
B10: Evidence triad | C10: Capture: (1) Atlas intent, (2) Inbox/approval card, (3) resulting record + report + Agent Run Ledger.
B12: Status legend
B13: Pass | C13: Fail | D13: Blocked | E13: N/A

Sheet Tenants
A1: The 10 Tenants
A3: # | B3: Tenant | C3: Market / Base ccy | D3: Firm type | E3: Size | F3: Complexity | G3: Signature dimension
A4: T1 | B4: Cobalt Consulting Co. | C4: US / USD | D4: Strategy boutique | E4: 8 | F4: Low | G4: Baseline smoke: T&M + one-offs, light SaaS procurement, monthly close
A5: T2 | B5: Pixel & Pulp Studio | C5: UK / GBP | D5: Creative + dev agency | E5: 30 | F5: Low-Med | G5: Milestone builds + multi-year retainers; capped-T&M overflow; EUR
A6: T3 | B6: Harborstone Accountants | C6: US / USD | D6: Accounting & tax firm | E6: 55 | F6: Med | G6: Fixed-fee milestones + per-event; scope creep; year-end statutory
A7: T4 | B7: Vantage Tax Partners | C7: Singapore / SGD | D7: Cross-border tax boutique | E7: 18 | F7: Med | G7: Multi-currency FX provenance; foreign-dividend journals; quarterly GST
A8: T5 | B8: Indus Engineering Advisory | C8: India / INR | D8: Engineering & PMO | E8: 90 | F8: Med-High | G8: 3-yr programs; HEAVY internal procurement; all AP edges; GST
A9: T6 | B9: Southern Cross Legal | C9: Australia / AUD | D9: Boutique law firm | E9: 22 | F9: Med | G9: Retainer-draw/trust; per-matter fixed; partial payments & disputes
A10: T7 | B10: Atlas Capital Advisors | C10: US / USD (+EUR/GBP) | D10: M&A / transaction advisory | E10: 40 | F10: High | G10: Success-fee milestones, estimate->actual; multi-currency deals
A11: T8 | B11: Helix Talent Group | C11: UK / GBP | D11: Recruitment & HR advisory | E11: 35 | F11: Med | G11: Per-placement + per-employee scaling + multi-year RPO retainers
A12: T9 | B12: Brightline Wealth Office | C12: UK / GBP (+SGD) | D12: Multi-entity family office | E12: 15 | F12: Very High | G12: One client = many entities; 7+ engagements; trusts; COSEC; privacy
A13: T10 | B13: Quantum Systems Integration | C13: US / USD (+EUR/GBP) | D13: Enterprise IT / SI | E13: 200 | F13: Extreme | G13: Everything: mixed-in-one engagement, full controls/audit, scheduled ops, red-team

Sheet Execution
A1: Execution Tracker
A2: Set Result per step. Capture the evidence triad. No backend seeding.
A4: Tenant | B4: Cycle | C4: Step | D4: Description (agentic-first action / prompt) | E4: Edge IDs | F4: Expected UI evidence | G4: Result | H4: Tester | I4: Date | J4: Notes
A5: T1 | B5: Setup | C5: S1.0 | D5: Sign up tenant (USD/US); create 4 roles; confirm tax + services; Stripe OFF first | F5: Tenant + users exist; Settings show tax rate
A6: T1 | B6: E2C | C6: S1.1 | D6: Atlas: log billable hours for Riverbend discovery | E6: EC-BILL-01 | F6: /time-entries row, billable
A7: T1 | B7: E2C | C7: S1.2 | D7: Atlas: process Riverbend travel receipt as billable expense | F7: /expenses row + receipt link
A8: T1 | B8: E2C | C8: S1.3 | D8: Atlas: June billing run -> Inbox -> approve | E8: EC-BILL-01 | F8: INV approved; DR AR/CR Revenue journal
A9: T1 | B9: E2C | C9: S1.4 | D9: Connect Stripe; Send; public link safety; pay test card; replay webhook | E9: EC-AR-06;EC-AGT-05 | F9: Invoice paid; DR Bank/CR AR; no duplicate payment
A10: T1 | B10: E2C | C10: S1.5 | D10: Calderon partial payment; Summit dual-approve race | E10: EC-AR-01;EC-CON-01 | F10: Remaining balance; one journal, loser 409
A11: T1 | B11: E2C | C11: S1.6 | D11: Velocity: AI-unavailable manual fallback invoice | E11: EC-AGT-04 | F11: Manual /invoices/new completes
A12: T1 | B12: E2C | C12: S1.7 | D12: Pinnacle zero-amount; Greenfield credit note | E12: EC-BILL-11;EC-BILL-12 | F12: No link/no-op; reverse journal
A13: T1 | B13: E2C | C13: S1.8 | D13: Northshore: Manager send blocked; Admin sends | E13: EC-RBAC-04 | F13: 403 for Manager; Admin/Owner sends
A14: T1 | B14: E2C | C14: S1.9 | D14: Collections read-only then draft >30d to Inbox; Hartwell cooldown | E14: EC-AR-04 | F14: Reminder cards in Inbox; cooldown blocked
A15: T1 | B15: P2P | C15: S1.10 | D15: SaaS bill intake -> approve -> bill-pay -> export -> sent -> settle | E15: EC-AP-12 | F15: DR Expense/CR AP; DR AP/CR Bank
A16: T1 | B16: R2R | C16: S1.11 | D16: Month-end close June -> lock; backdated post rejected | E16: EC-RR-01;EC-RR-04 | F16: Period lock; 422 period_locked
A17: T1 | B17: R2R | C17: S1.12 | D17: Statement package June vs May; reconcile to Reports | E17: EC-RR-13;EC-RR-14 | F17: TB balances; P&L/BS/CF render
A18: T1 | B18: Ctrl | C18: S1.13 | D18: Viewer approve attempt; decision trail; Agent Run Ledger | E18: EC-RBAC-01 | F18: Hidden + 403; trail + ledger reconcile
A19: T2 | B19: Setup | C19: S2.0 | D19: Sign up (GBP/UK); VAT20; Stripe on; roles | F19: Tenant/users; VAT seeded
A20: T2 | B20: E2C | C20: S2.1 | D20: Drop Aurora SOW -> engagement+project+rate card -> approve | F20: /engagements shows 3 milestones
A21: T2 | B21: E2C | C21: S2.2 | D21: Bill Milestone 1 then 2 across months | E21: EC-BILL-03 | F21: 2 invoices; WIP accrues between
A22: T2 | B22: E2C | C22: S2.3 | D22: Tideline 2-yr retainer run on the 1st -> Inbox -> approve | E22: EC-BILL-04 | F22: Recurring monthly retainer invoices
A23: T2 | B23: E2C | C23: S2.4 | D23: Beacon capped T&M: 89% alert then cap; overflow | E23: EC-BILL-06 | F23: Cap alert; non_billable_overflow
A24: T2 | B24: E2C | C24: S2.5 | D24: Kestrel mixed-model single invoice | E24: EC-BILL-07 | F24: Lines from fixed+retainer+T&M+expense
A25: T2 | B25: E2C | C25: S2.6 | D25: Lumiere EUR invoice; receipt FX move | E25: EC-FX-01;EC-FX-02 | F25: base_amount+fx_rate_id; realised FX 7900
A26: T2 | B26: E2C | C26: S2.7 | D26: Strata scope-creep supplemental engagement | E26: EC-BILL-10 | F26: Atlas cites comparable; new milestone
A27: T2 | B27: E2C | C27: S2.8 | D27: Verde learned-payer reminder suppression | E27: EC-AR-03 | F27: No reminder before learned pay day
A28: T2 | B28: P2P | C28: S2.9 | D28: Freelance subcontractor + recurring cloud bills | E28: EC-AP-11 | F28: 2nd cloud invoice auto-matches
A29: T2 | B29: P2P | C29: S2.10 | D29: Bill-pay lifecycle export->sent->settle | E29: EC-AP-12 | F29: Three recorded steps
A30: T2 | B30: R2R | C30: S2.11 | D30: Monthly close then Q2 package vs prior-yr Q2 | E30: EC-RR-01;EC-RR-02 | F30: Deterministic variances
A31: T2 | B31: R2R | C31: S2.12 | D31: Manual accrual journal; missing-reason rejected | E31: EC-RR-07;EC-RR-08 | F31: Posts w/ reason; 422 w/o
A32: T3 | B32: Setup | C32: S3.0 | D32: Sign up (USD); statutory+tax services; quarterly+YE | F32: COA/services set
A33: T3 | B33: E2C | C33: S3.1 | D33: Delmont 3-milestone annual accounts billed across year | E33: EC-BILL-03 | F33: Milestone recognition
A34: T3 | B34: E2C | C34: S3.2 | D34: Sandpiper per-event filings consolidated monthly | E34: EC-BILL-09 | F34: One consolidated invoice
A35: T3 | B35: E2C | C35: S3.3 | D35: Whitaker scope-creep supplemental | E35: EC-BILL-10 | F35: Comparable-fee citation
A36: T3 | B36: E2C | C36: S3.4 | D36: Sterling annual fee upfront -> deferred revenue | E36: EC-BILL-13 | F36: CR Deferred Revenue, released monthly
A37: T3 | B37: E2C | C37: S3.5 | D37: Foundry partial payment | E37: EC-AR-01 | F37: Remaining balance
A38: T3 | B38: P2P | C38: S3.6 | D38: Tax software + audit subcontractor; duplicate guard | E38: EC-AP-02;EC-AP-12 | F38: Approve-with-edits+reason; lifecycle
A39: T3 | B39: R2R | C39: S3.7 | D39: Monthly closes + Granite quarter-end review | E39: EC-RR-02 | F39: Comparative quarter
A40: T3 | B40: R2R | C40: S3.8 | D40: Year-end FY2026 close -> Inbox -> Owner approve | E40: EC-RR-03 | F40: year_end_close journal; dup blocked
A41: T3 | B41: R2R | C41: S3.9 | D41: Statement package + Statutory Pack FY26 vs FY25 | E41: EC-RR-13 | F41: TB balances; pack reconciles
...

Sheet Summary
A1: Coverage Summary
A3: Metric | B3: Count
A4: Total steps | B4: =COUNTA(Execution!A5:A118)
A5: Pass | B5: =COUNTIF(Execution!$G$5:$G$118,"Pass")
A6: Fail | B6: =COUNTIF(Execution!$G$5:$G$118,"Fail")
A7: Blocked | B7: =COUNTIF(Execution!$G$5:$G$118,"Blocked")
A8: N/A | B8: =COUNTIF(Execution!$G$5:$G$118,"N/A")
A9: Not yet run | B9: =COUNTBLANK(Execution!$G$5:$G$118)
A10: Pass rate | B10: =IF(COUNTA(Execution!A5:A118)=0,0,COUNTIF(Execution!$G$5:$G$118,"Pass")/COUNTA(Execution!A5:A118))
A12: By tenant
A13: Tenant | B13: Steps | C13: Pass | D13: Fail | E13: Blocked | F13: Not run | G13: Pass rate
A14: T1 | B14: =COUNTIF(Execution!$A$5:$A$118,"T1") | C14: =COUNTIFS(Execution!$A$5:$A$118,"T1",Execution!$G$5:$G$118,"Pass") | D14: =COUNTIFS(Execution!$A$5:$A$118,"T1",Execution!$G$5:$G$118,"Fail") | E14: =COUNTIFS(Execution!$A$5:$A$118,"T1",Execution!$G$5:$G$118,"Blocked") | F14: =COUNTIFS(Execution!$A$5:$A$118,"T1",Execution!$G$5:$G$118,"") | G14: =IF(B14=0,0,C14/B14)
A15: T2 | B15: =COUNTIF(Execution!$A$5:$A$118,"T2") | C15: =COUNTIFS(Execution!$A$5:$A$118,"T2",Execution!$G$5:$G$118,"Pass") | D15: =COUNTIFS(Execution!$A$5:$A$118,"T2",Execution!$G$5:$G$118,"Fail") | E15: =COUNTIFS(Execution!$A$5:$A$118,"T2",Execution!$G$5:$G$118,"Blocked") | F15: =COUNTIFS(Execution!$A$5:$A$118,"T2",Execution!$G$5:$G$118,"") | G15: =IF(B15=0,0,C15/B15)
A16: T3 | B16: =COUNTIF(Execution!$A$5:$A$118,"T3") | C16: =COUNTIFS(Execution!$A$5:$A$118,"T3",Execution!$G$5:$G$118,"Pass") | D16: =COUNTIFS(Execution!$A$5:$A$118,"T3",Execution!$G$5:$G$118,"Fail") | E16: =COUNTIFS(Execution!$A$5:$A$118,"T3",Execution!$G$5:$G$118,"Blocked") | F16: =COUNTIFS(Execution!$A$5:$A$118,"T3",Execution!$G$5:$G$118,"") | G16: =IF(B16=0,0,C16/B16)
A17: T4 | B17: =COUNTIF(Execution!$A$5:$A$118,"T4") | C17: =COUNTIFS(Execution!$A$5:$A$118,"T4",Execution!$G$5:$G$118,"Pass") | D17: =COUNTIFS(Execution!$A$5:$A$118,"T4",Execution!$G$5:$G$118,"Fail") | E17: =COUNTIFS(Execution!$A$5:$A$118,"T4",Execution!$G$5:$G$118,"Blocked") | F17: =COUNTIFS(Execution!$A$5:$A$118,"T4",Execution!$G$5:$G$118,"") | G17: =IF(B17=0,0,C17/B17)
A18: T5 | B18: =COUNTIF(Execution!$A$5:$A$118,"T5") | C18: =COUNTIFS(Execution!$A$5:$A$118,"T5",Execution!$G$5:$G$118,"Pass") | D18: =COUNTIFS(Execution!$A$5:$A$118,"T5",Execution!$G$5:$G$118,"Fail") | E18: =COUNTIFS(Execution!$A$5:$A$118,"T5",Execution!$G$5:$G$118,"Blocked") | F18: =COUNTIFS(Execution!$A$5:$A$118,"T5",Execution!$G$5:$G$118,"") | G18: =IF(B18=0,0,C18/B18)
A19: T6 | B19: =COUNTIF(Execution!$A$5:$A$118,"T6") | C19: =COUNTIFS(Execution!$A$5:$A$118,"T6",Execution!$G$5:$G$118,"Pass") | D19: =COUNTIFS(Execution!$A$5:$A$118,"T6",Execution!$G$5:$G$118,"Fail") | E19: =COUNTIFS(Execution!$A$5:$A$118,"T6",Execution!$G$5:$G$118,"Blocked") | F19: =COUNTIFS(Execution!$A$5:$A$118,"T6",Execution!$G$5:$G$118,"") | G19: =IF(B19=0,0,C19/B19)
A20: T7 | B20: =COUNTIF(Execution!$A$5:$A$118,"T7") | C20: =COUNTIFS(Execution!$A$5:$A$118,"T7",Execution!$G$5:$G$118,"Pass") | D20: =COUNTIFS(Execution!$A$5:$A$118,"T7",Execution!$G$5:$G$118,"Fail") | E20: =COUNTIFS(Execution!$A$5:$A$118,"T7",Execution!$G$5:$G$118,"Blocked") | F20: =COUNTIFS(Execution!$A$5:$A$118,"T7",Execution!$G$5:$G$118,"") | G20: =IF(B20=0,0,C20/B20)
A21: T8 | B21: =COUNTIF(Execution!$A$5:$A$118,"T8") | C21: =COUNTIFS(Execution!$A$5:$A$118,"T8",Execution!$G$5:$G$118,"Pass") | D21: =COUNTIFS(Execution!$A$5:$A$118,"T8",Execution!$G$5:$G$118,"Fail") | E21: =COUNTIFS(Execution!$A$5:$A$118,"T8",Execution!$G$5:$G$118,"Blocked") | F21: =COUNTIFS(Execution!$A$5:$A$118,"T8",Execution!$G$5:$G$118,"") | G21: =IF(B21=0,0,C21/B21)
A22: T9 | B22: =COUNTIF(Execution!$A$5:$A$118,"T9") | C22: =COUNTIFS(Execution!$A$5:$A$118,"T9",Execution!$G$5:$G$118,"Pass") | D22: =COUNTIFS(Execution!$A$5:$A$118,"T9",Execution!$G$5:$G$118,"Fail") | E22: =COUNTIFS(Execution!$A$5:$A$118,"T9",Execution!$G$5:$G$118,"Blocked") | F22: =COUNTIFS(Execution!$A$5:$A$118,"T9",Execution!$G$5:$G$118,"") | G22: =IF(B22=0,0,C22/B22)
A23: T10 | B23: =COUNTIF(Execution!$A$5:$A$118,"T10") | C23: =COUNTIFS(Execution!$A$5:$A$118,"T10",Execution!$G$5:$G$118,"Pass") | D23: =COUNTIFS(Execution!$A$5:$A$118,"T10",Execution!$G$5:$G$118,"Fail") | E23: =COUNTIFS(Execution!$A$5:$A$118,"T10",Execution!$G$5:$G$118,"Blocked") | F23: =COUNTIFS(Execution!$A$5:$A$118,"T10",Execution!$G$5:$G$118,"") | G23: =IF(B23=0,0,C23/B23)
